Workbook

Sheet  Cliente 7140341676
E1: COLUNA QTD UN/CX
A2: EAN | B2: Descrição | C2: SKU | D2: Categoria | E2: Quantidade
B3: =VLOOKUP(A3,'Mapa de Produto'!U:Y,5,0) -> #N/A | C3: =VLOOKUP(A3,'Mapa de Produto'!U:X,4,0) -> #N/A | D3: =VLOOKUP(C3,'Mapa de Produto'!G:P,10,0) -> #N/A
B4: =VLOOKUP(A4,'Mapa de Produto'!U:Y,5,0) -> #N/A | C4: =VLOOKUP(A4,'Mapa de Produto'!U:X,4,0) -> #N/A | D4: =VLOOKUP(C4,'Mapa de Produto'!G:P,10,0) -> #N/A
B5: =VLOOKUP(A5,'Mapa de Produto'!U:Y,5,0) -> #N/A | C5: =VLOOKUP(A5,'Mapa de Produto'!U:X,4,0) -> #N/A | D5: =VLOOKUP(C5,'Mapa de Produto'!G:P,10,0) -> #N/A
B6: =VLOOKUP(A6,'Mapa de Produto'!U:Y,5,0) -> #N/A | C6: =VLOOKUP(A6,'Mapa de Produto'!U:X,4,0) -> #N/A | D6: =VLOOKUP(C6,'Mapa de Produto'!G:P,10,0) -> #N/A
B7: =VLOOKUP(A7,'Mapa de Produto'!U:Y,5,0) -> #N/A | C7: =VLOOKUP(A7,'Mapa de Produto'!U:X,4,0) -> #N/A | D7: =VLOOKUP(C7,'Mapa de Produto'!G:P,10,0) -> #N/A
B8: =VLOOKUP(A8,'Mapa de Produto'!U:Y,5,0) -> #N/A | C8: =VLOOKUP(A8,'Mapa de Produto'!U:X,4,0) -> #N/A | D8: =VLOOKUP(C8,'Mapa de Produto'!G:P,10,0) -> #N/A
B9: =VLOOKUP(A9,'Mapa de Produto'!U:Y,5,0) -> #N/A | C9: =VLOOKUP(A9,'Mapa de Produto'!U:X,4,0) -> #N/A | D9: =VLOOKUP(C9,'Mapa de Produto'!G:P,10,0) -> #N/A
B10: =VLOOKUP(A10,'Mapa de Produto'!U:Y,5,0) -> #N/A | C10: =VLOOKUP(A10,'Mapa de Produto'!U:X,4,0) -> #N/A | D10: =VLOOKUP(C10,'Mapa de Produto'!G:P,10,0) -> #N/A
B11: =VLOOKUP(A11,'Mapa de Produto'!U:Y,5,0) -> #N/A | C11: =VLOOKUP(A11,'Mapa de Produto'!U:X,4,0) -> #N/A | D11: =VLOOKUP(C11,'Mapa de Produto'!G:P,10,0) -> #N/A
B12: =VLOOKUP(A12,'Mapa de Produto'!U:Y,5,0) -> #N/A | C12: =VLOOKUP(A12,'Mapa de Produto'!U:X,4,0) -> #N/A | D12: =VLOOKUP(C12,'Mapa de Produto'!G:P,10,0) -> #N/A
B13: =VLOOKUP(A13,'Mapa de Produto'!U:Y,5,0) -> #N/A | C13: =VLOOKUP(A13,'Mapa de Produto'!U:X,4,0) -> #N/A | D13: =VLOOKUP(C13,'Mapa de Produto'!G:P,10,0) -> #N/A
B14: =VLOOKUP(A14,'Mapa de Produto'!U:Y,5,0) -> #N/A | C14: =VLOOKUP(A14,'Mapa de Produto'!U:X,4,0) -> #N/A | D14: =VLOOKUP(C14,'Mapa de Produto'!G:P,10,0) -> #N/A
... B19: =VLOOKUP(A19,'Mapa de Produto'!U:Y,5,0) -> #N/A | C19: =VLOOKUP(A19,'Mapa de Produto'!U:X,4,0) -> #N/A | D19: =VLOOKUP(C19,'Mapa de Produto'!G:P,10,0) -> #N/A
B20: =VLOOKUP(A20,'Mapa de Produto'!U:Y,5,0) -> #N/A | C20: =VLOOKUP(A20,'Mapa de Produto'!U:X,4,0) -> #N/A | D20: =VLOOKUP(C20,'Mapa de Produto'!G:P,10,0) -> #N/A | H20: REFERÊNCIA = EAN | N20: QUANTIDADE
B21: =VLOOKUP(A21,'Mapa de Produto'!U:Y,5,0) -> #N/A | C21: =VLOOKUP(A21,'Mapa de Produto'!U:X,4,0) -> #N/A | D21: =VLOOKUP(C21,'Mapa de Produto'!G:P,10,0) -> #N/A
B22: =VLOOKUP(A22,'Mapa de Produto'!U:Y,5,0) -> #N/A | C22: =VLOOKUP(A22,'Mapa de Produto'!U:X,4,0) -> #N/A | D22: =VLOOKUP(C22,'Mapa de Produto'!G:P,10,0) -> #N/A
B23: =VLOOKUP(A23,'Mapa de Produto'!U:Y,5,0) -> #N/A | C23: =VLOOKUP(A23,'Mapa de Produto'!U:X,4,0) -> #N/A | D23: =VLOOKUP(C23,'Mapa de Produto'!G:P,10,0) -> #N/A
B24: =VLOOKUP(A24,'Mapa de Produto'!U:Y,5,0) -> #N/A | C24: =VLOOKUP(A24,'Mapa de Produto'!U:X,4,0) -> #N/A | D24: =VLOOKUP(C24,'Mapa de Produto'!G:P,10,0) -> #N/A
B25: =VLOOKUP(A25,'Mapa de Produto'!U:Y,5,0) -> #N/A | C25: =VLOOKUP(A25,'Mapa de Produto'!U:X,4,0) -> #N/A | D25: =VLOOKUP(C25,'Mapa de Produto'!G:P,10,0) -> #N/A
B26: =VLOOKUP(A26,'Mapa de Produto'!U:Y,5,0) -> #N/A | C26: =VLOOKUP(A26,'Mapa de Produto'!U:X,4,0) -> #N/A | D26: =VLOOKUP(C26,'Mapa de Produto'!G:P,10,0) -> #N/A
B27: =VLOOKUP(A27,'Mapa de Produto'!U:Y,5,0) -> #N/A | C27: =VLOOKUP(A27,'Mapa de Produto'!U:X,4,0) -> #N/A | D27: =VLOOKUP(C27,'Mapa de Produto'!G:P,10,0) -> #N/A
B28: =VLOOKUP(A28,'Mapa de Produto'!U:Y,5,0) -> #N/A | C28: =VLOOKUP(A28,'Mapa de Produto'!U:X,4,0) -> #N/A | D28: =VLOOKUP(C28,'Mapa de Produto'!G:P,10,0) -> #N/A
B29: =VLOOKUP(A29,'Mapa de Produto'!U:Y,5,0) -> #N/A | C29: =VLOOKUP(A29,'Mapa de Produto'!U:X,4,0) -> #N/A | D29: =VLOOKUP(C29,'Mapa de Produto'!G:P,10,0) -> #N/A
B30: =VLOOKUP(A30,'Mapa de Produto'!U:Y,5,0) -> #N/A | C30: =VLOOKUP(A30,'Mapa de Produto'!U:X,4,0) -> #N/A | D30: =VLOOKUP(C30,'Mapa de Produto'!G:P,10,0) -> #N/A
B31: =VLOOKUP(A31,'Mapa de Produto'!U:Y,5,0) -> #N/A | C31: =VLOOKUP(A31,'Mapa de Produto'!U:X,4,0) -> #N/A | D31: =VLOOKUP(C31,'Mapa de Produto'!G:P,10,0) -> #N/A
B32: =VLOOKUP(A32,'Mapa de Produto'!U:Y,5,0) -> #N/A | C32: =VLOOKUP(A32,'Mapa de Produto'!U:X,4,0) -> #N/A | D32: =VLOOKUP(C32,'Mapa de Produto'!G:P,10,0) -> #N/A
... B53: =VLOOKUP(A53,'Mapa de Produto'!U:Y,5,0) -> #N/A | C53: =VLOOKUP(A53,'Mapa de Produto'!U:X,4,0) -> #N/A | D53: =VLOOKUP(C53,'Mapa de Produto'!G:P,10,0) -> #N/A
B54: =VLOOKUP(A54,'Mapa de Produto'!U:Y,5,0) -> #N/A | C54: =VLOOKUP(A54,'Mapa de Produto'!U:X,4,0) -> #N/A | D54: =VLOOKUP(C54,'Mapa de Produto'!G:P,10,0) -> #N/A | E54: 3
B55: =VLOOKUP(A55,'Mapa de Produto'!U:Y,5,0) -> #N/A | C55: =VLOOKUP(A55,'Mapa de Produto'!U:X,4,0) -> #N/A | D55: =VLOOKUP(C55,'Mapa de Produto'!G:P,10,0) -> #N/A
B56: =VLOOKUP(A56,'Mapa de Produto'!U:Y,5,0) -> #N/A | C56: =VLOOKUP(A56,'Mapa de Produto'!U:X,4,0) -> #N/A | D56: =VLOOKUP(C56,'Mapa de Produto'!G:P,10,0) -> #N/A
B57: =VLOOKUP(A57,'Mapa de Produto'!U:Y,5,0) -> #N/A | C57: =VLOOKUP(A57,'Mapa de Produto'!U:X,4,0) -> #N/A | D57: =VLOOKUP(C57,'Mapa de Produto'!G:P,10,0) -> #N/A
B58: =VLOOKUP(A58,'Mapa de Produto'!U:Y,5,0) -> #N/A | C58: =VLOOKUP(A58,'Mapa de Produto'!U:X,4,0) -> #N/A | D58: =VLOOKUP(C58,'Mapa de Produto'!G:P,10,0) -> #N/A
B59: =VLOOKUP(A59,'Mapa de Produto'!U:Y,5,0) -> #N/A | C59: =VLOOKUP(A59,'Mapa de Produto'!U:X,4,0) -> #N/A | D59: =VLOOKUP(C59,'Mapa de Produto'!G:P,10,0) -> #N/A
B60: =VLOOKUP(A60,'Mapa de Produto'!U:Y,5,0) -> #N/A | C60: =VLOOKUP(A60,'Mapa de Produto'!U:X,4,0) -> #N/A | D60: =VLOOKUP(C60,'Mapa de Produto'!G:P,10,0) -> #N/A
B61: =VLOOKUP(A61,'Mapa de Produto'!U:Y,5,0) -> #N/A | C61: =VLOOKUP(A61,'Mapa de Produto'!U:X,4,0) -> #N/A | D61: =VLOOKUP(C61,'Mapa de Produto'!G:P,10,0) -> #N/A
B62: =VLOOKUP(A62,'Mapa de Produto'!U:Y,5,0) -> #N/A | C62: =VLOOKUP(A62,'Mapa de Produto'!U:X,4,0) -> #N/A | D62: =VLOOKUP(C62,'Mapa de Produto'!G:P,10,0) -> #N/A
B63: =VLOOKUP(A63,'Mapa de Produto'!U:Y,5,0) -> #N/A | C63: =VLOOKUP(A63,'Mapa de Produto'!U:X,4,0) -> #N/A | D63: =VLOOKUP(C63,'Mapa de Produto'!G:P,10,0) -> #N/A
B64: =VLOOKUP(A64,'Mapa de Produto'!U:Y,5,0) -> #N/A | C64: =VLOOKUP(A64,'Mapa de Produto'!U:X,4,0) -> #N/A | D64: =VLOOKUP(C64,'Mapa de Produto'!G:P,10,0) -> #N/A
...

Sheet GABARITO
A1: EAN | B1: Descrição | C1: SKU | D1: Categoria | E1: Caixaria Cliente | F1: Quantidade
B2: =VLOOKUP(A2,'LISTA DE PRODUTOS'!B:D,3,0) -> #N/A | C2: =VLOOKUP(A2,'LISTA DE PRODUTOS'!B:C,2,0) -> #N/A | D2: =VLOOKUP(A2,'LISTA DE PRODUTOS'!B:E,4,0) -> #N/A
B3: =VLOOKUP(A3,'LISTA DE PRODUTOS'!B:D,3,0) -> #N/A | C3: =VLOOKUP(A3,'LISTA DE PRODUTOS'!B:C,2,0) -> #N/A | D3: =VLOOKUP(A3,'LISTA DE PRODUTOS'!B:E,4,0) -> #N/A
B4: =VLOOKUP(A4,'LISTA DE PRODUTOS'!B:D,3,0) -> #N/A | C4: =VLOOKUP(A4,'LISTA DE PRODUTOS'!B:C,2,0) -> #N/A | D4: =VLOOKUP(A4,'LISTA DE PRODUTOS'!B:E,4,0) -> #N/A
B5: =VLOOKUP(A5,'LISTA DE PRODUTOS'!B:D,3,0) -> #N/A | C5: =VLOOKUP(A5,'LISTA DE PRODUTOS'!B:C,2,0) -> #N/A | D5: =VLOOKUP(A5,'LISTA DE PRODUTOS'!B:E,4,0) -> #N/A
B6: =VLOOKUP(A6,'LISTA DE PRODUTOS'!B:D,3,0) -> #N/A | C6: =VLOOKUP(A6,'LISTA DE PRODUTOS'!B:C,2,0) -> #N/A | D6: =VLOOKUP(A6,'LISTA DE PRODUTOS'!B:E,4,0) -> #N/A
B7: =VLOOKUP(A7,'LISTA DE PRODUTOS'!B:D,3,0) -> #N/A | C7: =VLOOKUP(A7,'LISTA DE PRODUTOS'!B:C,2,0) -> #N/A | D7: =VLOOKUP(A7,'LISTA DE PRODUTOS'!B:E,4,0) -> #N/A
B8: =VLOOKUP(A8,'LISTA DE PRODUTOS'!B:D,3,0) -> #N/A | C8: =VLOOKUP(A8,'LISTA DE PRODUTOS'!B:C,2,0) -> #N/A | D8: =VLOOKUP(A8,'LISTA DE PRODUTOS'!B:E,4,0) -> #N/A
B9: =VLOOKUP(A9,'LISTA DE PRODUTOS'!B:D,3,0) -> #N/A | C9: =VLOOKUP(A9,'LISTA DE PRODUTOS'!B:C,2,0) -> #N/A | D9: =VLOOKUP(A9,'LISTA DE PRODUTOS'!B:E,4,0) -> #N/A
B10: =VLOOKUP(A10,'LISTA DE PRODUTOS'!B:D,3,0) -> #N/A | C10: =VLOOKUP(A10,'LISTA DE PRODUTOS'!B:C,2,0) -> #N/A | D10: =VLOOKUP(A10,'LISTA DE PRODUTOS'!B:E,4,0) -> #N/A
B11: =VLOOKUP(A11,'LISTA DE PRODUTOS'!B:D,3,0) -> #N/A | C11: =VLOOKUP(A11,'LISTA DE PRODUTOS'!B:C,2,0) -> #N/A | D11: =VLOOKUP(A11,'LISTA DE PRODUTOS'!B:E,4,0) -> #N/A
B12: =VLOOKUP(A12,'LISTA DE PRODUTOS'!B:D,3,0) -> #N/A | C12: =VLOOKUP(A12,'LISTA DE PRODUTOS'!B:C,2,0) -> #N/A | D12: =VLOOKUP(A12,'LISTA DE PRODUTOS'!B:E,4,0) -> #N/A
B13: =VLOOKUP(A13,'LISTA DE PRODUTOS'!B:D,3,0) -> #N/A | C13: =VLOOKUP(A13,'LISTA DE PRODUTOS'!B:C,2,0) -> #N/A | D13: =VLOOKUP(A13,'LISTA DE PRODUTOS'!B:E,4,0) -> #N/A
... B15: =VLOOKUP(A15,'LISTA DE PRODUTOS'!B:D,3,0) -> #N/A | C15: =VLOOKUP(A15,'LISTA DE PRODUTOS'!B:C,2,0) -> #N/A | D15: =VLOOKUP(A15,'LISTA DE PRODUTOS'!B:E,4,0) -> #N/A
B16: =VLOOKUP(A16,'LISTA DE PRODUTOS'!B:D,3,0) -> #N/A | C16: =VLOOKUP(A16,'LISTA DE PRODUTOS'!B:C,2,0) -> #N/A | D16: =VLOOKUP(A16,'LISTA DE PRODUTOS'!B:E,4,0) -> #N/A | J16: QUANTIDADE
B17: =VLOOKUP(A17,'LISTA DE PRODUTOS'!B:D,3,0) -> #N/A | C17: =VLOOKUP(A17,'LISTA DE PRODUTOS'!B:C,2,0) -> #N/A | D17: =VLOOKUP(A17,'LISTA DE PRODUTOS'!B:E,4,0) -> #N/A | H17: REFERÊNCIA = EAN
B18: =VLOOKUP(A18,'LISTA DE PRODUTOS'!B:D,3,0) -> #N/A | C18: =VLOOKUP(A18,'LISTA DE PRODUTOS'!B:C,2,0) -> #N/A | D18: =VLOOKUP(A18,'LISTA DE PRODUTOS'!B:E,4,0) -> #N/A
B19: =VLOOKUP(A19,'LISTA DE PRODUTOS'!B:D,3,0) -> #N/A | C19: =VLOOKUP(A19,'LISTA DE PRODUTOS'!B:C,2,0) -> #N/A | D19: =VLOOKUP(A19,'LISTA DE PRODUTOS'!B:E,4,0) -> #N/A
B20: =VLOOKUP(A20,'LISTA DE PRODUTOS'!B:D,3,0) -> #N/A | C20: =VLOOKUP(A20,'LISTA DE PRODUTOS'!B:C,2,0) -> #N/A | D20: =VLOOKUP(A20,'LISTA DE PRODUTOS'!B:E,4,0) -> #N/A
B21: =VLOOKUP(A21,'LISTA DE PRODUTOS'!B:D,3,0) -> #N/A | C21: =VLOOKUP(A21,'LISTA DE PRODUTOS'!B:C,2,0) -> #N/A | D21: =VLOOKUP(A21,'LISTA DE PRODUTOS'!B:E,4,0) -> #N/A
B22: =VLOOKUP(A22,'LISTA DE PRODUTOS'!B:D,3,0) -> #N/A | C22: =VLOOKUP(A22,'LISTA DE PRODUTOS'!B:C,2,0) -> #N/A | D22: =VLOOKUP(A22,'LISTA DE PRODUTOS'!B:E,4,0) -> #N/A
B23: =VLOOKUP(A23,'LISTA DE PRODUTOS'!B:D,3,0) -> #N/A | C23: =VLOOKUP(A23,'LISTA DE PRODUTOS'!B:C,2,0) -> #N/A | D23: =VLOOKUP(A23,'LISTA DE PRODUTOS'!B:E,4,0) -> #N/A
B24: =VLOOKUP(A24,'LISTA DE PRODUTOS'!B:D,3,0) -> #N/A | C24: =VLOOKUP(A24,'LISTA DE PRODUTOS'!B:C,2,0) -> #N/A | D24: =VLOOKUP(A24,'LISTA DE PRODUTOS'!B:E,4,0) -> #N/A
B25: =VLOOKUP(A25,'LISTA DE PRODUTOS'!B:D,3,0) -> #N/A | C25: =VLOOKUP(A25,'LISTA DE PRODUTOS'!B:C,2,0) -> #N/A | D25: =VLOOKUP(A25,'LISTA DE PRODUTOS'!B:E,4,0) -> #N/A
B26: =VLOOKUP(A26,'LISTA DE PRODUTOS'!B:D,3,0) -> #N/A | C26: =VLOOKUP(A26,'LISTA DE PRODUTOS'!B:C,2,0) -> #N/A | D26: =VLOOKUP(A26,'LISTA DE PRODUTOS'!B:E,4,0) -> #N/A
B27: =VLOOKUP(A27,'LISTA DE PRODUTOS'!B:D,3,0) -> #N/A | C27: =VLOOKUP(A27,'LISTA DE PRODUTOS'!B:C,2,0) -> #N/A | D27: =VLOOKUP(A27,'LISTA DE PRODUTOS'!B:E,4,0) -> #N/A
B28: =VLOOKUP(A28,'LISTA DE PRODUTOS'!B:D,3,0) -> #N/A | C28: =VLOOKUP(A28,'LISTA DE PRODUTOS'!B:C,2,0) -> #N/A | D28: =VLOOKUP(A28,'LISTA DE PRODUTOS'!B:E,4,0) -> #N/A
B29: =VLOOKUP(A29,'LISTA DE PRODUTOS'!B:D,3,0) -> #N/A | C29: =VLOOKUP(A29,'LISTA DE PRODUTOS'!B:C,2,0) -> #N/A | D29: =VLOOKUP(A29,'LISTA DE PRODUTOS'!B:E,4,0) -> #N/A
... B122: =VLOOKUP(A122,'LISTA DE PRODUTOS'!B:D,3,0) -> #N/A | C122: =VLOOKUP(A122,'LISTA DE PRODUTOS'!B:C,2,0) -> #N/A | D122: =VLOOKUP(A122,'LISTA DE PRODUTOS'!B:E,4,0) -> #N/A

Sheet Mapa de Produto
A1: STR1 | B1: STR2 | C1: STR3 | D1: SKU Rolling | E1: Descrição SKU Rolling | F1: Centro | G1: SKU ECC | H1: Descrição SKU ECC | I1: Categoria | J1: Tipo Produção | K1: Fator PAL | L1: Apresentação | M1: Nome UO | N1: Regional | O1: MAPA | P1: Categoria PD | Q1: OBSERVAÇÃO | R1: Data Lançamento | S1: Migração | T1: Código DUN | U1: Código EAN | V1: COD CVI | W1: CIA | X1: SKU ECC | Y1: Descrição SKU ECC
A2: BFGGCrystal C/G PET 1,5L (06) | B2: BFGG83 | C2: BFGG92520 | D2: 83 | E2: Crystal C/G PET 1,5L (06) | F2: BFGG | G2: 92520 | H2: CRYSTAL 1,5L COM GÁS 06UN | I2: AGUA | J2: Produzido | K2: 112 | L2: 6 | M2: UO Santa Maria | N2: RS INT | O2: S | P2: AGUA | T2: 17894900531012 | U2: 7894900531015 | V2: 1023 | W2: KO | X2: =G2 -> 92520 | Y2: CRYSTAL 1,5L COM GÁS 06UN
A3: BFGHCrystal C/G PET 1,5L (06) | B3: BFGH83 | C3: BFGH92520 | D3: 83 | E3: Crystal C/G PET 1,5L (06) | F3: BFGH | G3: 92520 | H3: CRYSTAL 1,5L COM GÁS 06UN | I3: AGUA | J3: Produzido | K3: 112 | L3: 6 | M3: UO Passo Fundo | N3: RS INT | O3: S | P3: AGUA | T3: 17894900531012 | U3: 7894900531015 | V3: 1023 | W3: KO | X3: =G3 -> 92520 | Y3: CRYSTAL 1,5L COM GÁS 06UN
A4: BFGICrystal C/G PET 1,5L (06) | B4: BFGI83 | C4: BFGI92520 | D4: 83 | E4: Crystal C/G PET 1,5L (06) | F4: BFGI | G4: 92520 | H4: CRYSTAL 1,5L COM GÁS 06UN | I4: AGUA | J4: Produzido | K4: 112 | L4: 6 | M4: UO Vera Cruz | N4: RS INT | O4: S | P4: AGUA | T4: 17894900531012 | U4: 7894900531015 | V4: 1023 | W4: KO | X4: =G4 -> 92520 | Y4: CRYSTAL 1,5L COM GÁS 06UN
A5: BFGGCrystal C/G PET 500ml (12) | B5: BFGG708 | C5: BFGG92522 | D5: 708 | E5: Crystal C/G PET 500ml (12) | F5: BFGG | G5: 92522 | H5: CRYSTAL 500ML COM GÁS 12UN | I5: AGUA | J5: Produzido | K5: 150 | L5: 12 | M5: UO Santa Maria | N5: RS INT | O5: S | P5: AGUA | T5: 17894900531005 | U5: 7894900531008 | V5: 1021 | W5: KO | X5: =G5 -> 92522 | Y5: CRYSTAL 500ML COM GÁS 12UN
A6: BFGHCrystal C/G PET 500ml (12) | B6: BFGH708 | C6: BFGH92522 | D6: 708 | E6: Crystal C/G PET 500ml (12) | F6: BFGH | G6: 92522 | H6: CRYSTAL 500ML COM GÁS 12UN | I6: AGUA | J6: Produzido | K6: 150 | L6: 12 | M6: UO Passo Fundo | N6: RS INT | O6: S | P6: AGUA | T6: 17894900531005 | U6: 7894900531008 | V6: 1021 | W6: KO | X6: =G6 -> 92522 | Y6: CRYSTAL 500ML COM GÁS 12UN
A7: BFGICrystal C/G PET 500ml (12) | B7: BFGI708 | C7: BFGI92522 | D7: 708 | E7: Crystal C/G PET 500ml (12) | F7: BFGI | G7: 92522 | H7: CRYSTAL 500ML COM GÁS 12UN | I7: AGUA | J7: Produzido | K7: 150 | L7: 12 | M7: UO Vera Cruz | N7: RS INT | O7: S | P7: AGUA | T7: 17894900531005 | U7: 7894900531008 | V7: 1021 | W7: KO | X7: =G7 -> 92522 | Y7: CRYSTAL 500ML COM GÁS 12UN
A8: BFGGCrystal Copo 310ml (48) | B8: BFGG85 | C8: BFGG92536 | D8: 85 | E8: Crystal Copo 310ml (48) | F8: BFGG | G8: 92536 | H8: CRYSTAL COPO 310ML SG 48UN CP . | I8: AGUA | J8: Produzido | K8: 60 | L8: 48 | M8: UO Santa Maria | N8: RS INT | O8: L10 | P8: AGUA | Q8: Data a definir | R8: 44835 | T8: 7894900530148 | U8: 7894900530049 | V8: Sem Sku Correspondente | W8: KO | X8: =G8 -> 92536 | Y8: CRYSTAL COPO 310ML SG 48UN CP .
A9: BFGHCrystal Copo 310ml (48) | B9: BFGH85 | C9: BFGH92536 | D9: 85 | E9: Crystal Copo 310ml (48) | F9: BFGH | G9: 92536 | H9: CRYSTAL COPO 310ML SG 48UN CP . | I9: AGUA | J9: Produzido | K9: 60 | L9: 48 | M9: UO Passo Fundo | N9: RS INT | O9: L10 | P9: AGUA | Q9: Data a definir | R9: 44835 | T9: 7894900530148 | U9: 7894900530049 | V9: Sem Sku Correspondente | W9: KO | X9: =G9 -> 92536 | Y9: CRYSTAL COPO 310ML SG 48UN CP .
A10: BFGICrystal Copo 310ml (48) | B10: BFGI85 | C10: BFGI92536 | D10: 85 | E10: Crystal Copo 310ml (48) | F10: BFGI | G10: 92536 | H10: CRYSTAL COPO 310ML SG 48UN CP . | I10: AGUA | J10: Produzido | K10: 60 | L10: 48 | M10: UO Vera Cruz | N10: RS INT | O10: L10 | P10: AGUA | Q10: Data a definir | R10: 44835 | T10: 7894900530148 | U10: 7894900530049 | V10: Sem Sku Correspondente | W10: KO | X10: =G10 -> 92536 | Y10: CRYSTAL COPO 310ML SG 48UN CP .
A11: BFGGCrystal PET 5L (02) | B11: BFGG94 | C11: BFGG92581 | D11: 94 | E11: Crystal PET 5L (02) | F11: BFGG | G11: 92581 | H11: CRYSTAL 05L C/2 CP | I11: AGUA | J11: Produzido | K11: 112 | L11: 2 | M11: UO Santa Maria | N11: RS INT | O11: S | P11: AGUA | T11: 17894900530053 | U11: 7894900530056 | V11: 1088 | W11: KO | X11: =G11 -> 92581 | Y11: CRYSTAL 05L C/2 CP
A12: BFGHCrystal PET 5L (02) | B12: BFGH94 | C12: BFGH92581 | D12: 94 | E12: Crystal PET 5L (02) | F12: BFGH | G12: 92581 | H12: CRYSTAL 05L C/2 CP | I12: AGUA | J12: Produzido | K12: 112 | L12: 2 | M12: UO Passo Fundo | N12: RS INT | O12: S | P12: AGUA | T12: 17894900530053 | U12: 7894900530056 | V12: 1088 | W12: KO | X12: =G12 -> 92581 | Y12: CRYSTAL 05L C/2 CP
A13: BFGICrystal PET 5L (02) | B13: BFGI94 | C13: BFGI92581 | D13: 94 | E13: Crystal PET 5L (02) | F13: BFGI | G13: 92581 | H13: CRYSTAL 05L C/2 CP | I13: AGUA | J13: Produzido | K13: 112 | L13: 2 | M13: UO Vera Cruz | N13: RS INT | O13: S | P13: AGUA | T13: 17894900530053 | U13: 7894900530056 | V13: 1088 | W13: KO | X13: =G13 -> 92581 | Y13: CRYSTAL 05L C/2 CP
A14: BFGGCrystal S/G PET 1,5L (06) | B14: BFGG84 | C14: BFGG92521 | D14: 84 | E14: Crystal S/G PET 1,5L (06) | F14: BFGG | G14: 92521 | H14: CRYSTAL 1,5L SEM GÁS 06UN | I14: AGUA | J14: Produzido | K14: 112 | L14: 6 | M14: UO Santa Maria | N14: RS INT | O14: S | P14: AGUA | T14: 17894900530039 | U14: 7894900530032 | V14: 1024 | W14: KO | X14: =G14 -> 92521 | Y14: CRYSTAL 1,5L SEM GÁS 06UN
A15: BFGHCrystal S/G PET 1,5L (06) | B15: BFGH84 | C15: BFGH92521 | D15: 84 | E15: Crystal S/G PET 1,5L (06) | F15: BFGH | G15: 92521 | H15: CRYSTAL 1,5L SEM GÁS 06UN | I15: AGUA | J15: Produzido | K15: 112 | L15: 6 | M15: UO Passo Fundo | N15: RS INT | O15: S | P15: AGUA | T15: 17894900530039 | U15: 7894900530032 | V15: 1024 | W15: KO | X15: =G15 -> 92521 | Y15: CRYSTAL 1,5L SEM GÁS 06UN
A16: BFGICrystal S/G PET 1,5L (06) | B16: BFGI84 | C16: BFGI92521 | D16: 84 | E16: Crystal S/G PET 1,5L (06) | F16: BFGI | G16: 92521 | H16: CRYSTAL 1,5L SEM GÁS 06UN | I16: AGUA | J16: Produzido | K16: 112 | L16: 6 | M16: UO Vera Cruz | N16: RS INT | O16: S | P16: AGUA | T16: 17894900530039 | U16: 7894900530032 | V16: 1024 | W16: KO | X16: =G16 -> 92521 | Y16: CRYSTAL 1,5L SEM GÁS 06UN
A17: BFGGCrystal S/G PET 1,5L (08) L+P- | B17: BFGG1246 | C17: BFGG92670 | D17: 1246 | E17: Crystal S/G PET 1,5L (08) L+P- | F17: BFGG | G17: 92670 | H17: CRYST 1,5L SEM GÁS 08UN PROM FI CP | I17: AGUA | J17: Produzido | K17: 84 | L17: 8 | M17: UO Santa Maria | N17: RS INT | O17: L10 | P17: AGUA | Q17: Data a definir | R17: 44835 | T17: 7894900530278 | U17: 7894900530032 | V17: Sem Sku Correspondente | W17: KO | X17: =G17 -> 92670 | Y17: CRYST 1,5L SEM GÁS 08UN PROM FI CP
A18: BFGHCrystal S/G PET 1,5L (08) L+P- | B18: BFGH1246 | C18: BFGH92670 | D18: 1246 | E18: Crystal S/G PET 1,5L (08) L+P- | F18: BFGH | G18: 92670 | H18: CRYST 1,5L SEM GÁS 08UN PROM FI CP | I18: AGUA | J18: Produzido | K18: 84 | L18: 8 | M18: UO Passo Fundo | N18: RS INT | O18: L10 | P18: AGUA | Q18: Data a definir | R18: 44835 | T18: 7894900530278 | U18: 7894900530032 | V18: Sem Sku Correspondente | W18: KO | X18: =G18 -> 92670 | Y18: CRYST 1,5L SEM GÁS 08UN PROM FI CP
A19: BFGICrystal S/G PET 1,5L (08) L+P- | B19: BFGI1246 | C19: BFGI92670 | D19: 1246 | E19: Crystal S/G PET 1,5L (08) L+P- | F19: BFGI | G19: 92670 | H19: CRYST 1,5L SEM GÁS 08UN PROM FI CP | I19: AGUA | J19: Produzido | K19: 84 | L19: 8 | M19: UO Vera Cruz | N19: RS INT | O19: L10 | P19: AGUA | Q19: Data a definir | R19: 44835 | T19: 7894900530278 | U19: 7894900530032 | V19: Sem Sku Correspondente | W19: KO | X19: =G19 -> 92670 | Y19: CRYST 1,5L SEM GÁS 08UN PROM FI CP
A20: BFGGCrystal S/G PET 500ml (12) | B20: BFGG709 | C20: BFGG92527 | D20: 709 | E20: Crystal S/G PET 500ml (12) | F20: BFGG | G20: 92527 | H20: CRYSTAL 500ML SEM GÁS 12UN | I20: AGUA | J20: Produzido | K20: 150 | L20: 12 | M20: UO Santa Maria | N20: RS INT | O20: S | P20: AGUA | T20: 17894900530008 | U20: 7894900530001 | V20: 1022 | W20: KO | X20: =G20 -> 92527 | Y20: CRYSTAL 500ML SEM GÁS 12UN
A21: BFGHCrystal S/G PET 500ml (12) | B21: BFGH709 | C21: BFGH92527 | D21: 709 | E21: Crystal S/G PET 500ml (12) | F21: BFGH | G21: 92527 | H21: CRYSTAL 500ML SEM GÁS 12UN | I21: AGUA | J21: Produzido | K21: 150 | L21: 12 | M21: UO Passo Fundo | N21: RS INT | O21: S | P21: AGUA | T21: 17894900530008 | U21: 7894900530001 | V21: 1022 | W21: KO | X21: =G21 -> 92527 | Y21: CRYSTAL 500ML SEM GÁS 12UN
A22: BFGICrystal S/G PET 500ml (12) | B22: BFGI709 | C22: BFGI92527 | D22: 709 | E22: Crystal S/G PET 500ml (12) | F22: BFGI | G22: 92527 | H22: CRYSTAL 500ML SEM GÁS 12UN | I22: AGUA | J22: Produzido | K22: 150 | L22: 12 | M22: UO Vera Cruz | N22: RS INT | O22: S | P22: AGUA | T22: 17894900530008 | U22: 7894900530001 | V22: 1022 | W22: KO | X22: =G22 -> 92527 | Y22: CRYSTAL 500ML SEM GÁS 12UN
A23: BFGGCrystal Sabores Frutas Vermelhas PET 510ml (06) | B23: BFGG1453 | C23: BFGG92723 | D23: 1453 | E23: Crystal Sabores Frutas Vermelhas PET 510ml (06) | F23: BFGG | G23: 92723 | H23: CRY SPARKLING FRUTAS VERM PET510 6U FL | I23: AGUA | J23: Produzido | K23: 392 | L23: 6 | M23: UO Santa Maria | N23: RS INT | O23: S | P23: AGUA | T23: 17894900521501 | U23: 7894900521504 | V23: 1279 | W23: KO | X23: =G23 -> 92723 | Y23: CRY SPARKLING FRUTAS VERM PET510 6U FL
A24: BFGHCrystal Sabores Frutas Vermelhas PET 510ml (06) | B24: BFGH1453 | C24: BFGH92723 | D24: 1453 | E24: Crystal Sabores Frutas Vermelhas PET 510ml (06) | F24: BFGH | G24: 92723 | H24: CRY SPARKLING FRUTAS VERM PET510 6U FL | I24: AGUA | J24: Produzido | K24: 392 | L24: 6 | M24: UO Passo Fundo | N24: RS INT | O24: S | P24: AGUA | T24: 17894900521501 | U24: 7894900521504 | V24: 1279 | W24: KO | X24: =G24 -> 92723 | Y24: CRY SPARKLING FRUTAS VERM PET510 6U FL
A25: BFGICrystal Sabores Frutas Vermelhas PET 510ml (06) | B25: BFGI1453 | C25: BFGI92723 | D25: 1453 | E25: Crystal Sabores Frutas Vermelhas PET 510ml (06) | F25: BFGI | G25: 92723 | H25: CRY SPARKLING FRUTAS VERM PET510 6U FL | I25: AGUA | J25: Produzido | K25: 392 | L25: 6 | M25: UO Vera Cruz | N25: RS INT | O25: S | P25: AGUA | T25: 17894900521501 | U25: 7894900521504 | V25: 1279 | W25: KO | X25: =G25 -> 92723 | Y25: CRY SPARKLING FRUTAS VERM PET510 6U FL
A26: BFGGCrystal Sabores Limao PET 510ml (06) | B26: BFGG1452 | C26: BFGG92721 | D26: 1452 | E26: Crystal Sabores Limao PET 510ml (06) | F26: BFGG | G26: 92721 | H26: CRY SPARKLING LIMAO PET 510ml 6U FL | I26: AGUA | J26: Produzido | K26: 392 | L26: 6 | M26: UO Santa Maria | N26: RS INT | O26: S | P26: AGUA | T26: 17894900520504 | U26: 7894900520507 | V26: 1280 | W26: KO | X26: =G26 -> 92721 | Y26: CRY SPARKLING LIMAO PET 510ml 6U FL
A27: BFGHCrystal Sabores Limao PET 510ml (06) | B27: BFGH1452 | C27: BFGH92721 | D27: 1452 | E27: Crystal Sabores Limao PET 510ml (06) | F27: BFGH | G27: 92721 | H27: CRY SPARKLING LIMAO PET 510ml 6U FL | I27: AGUA | J27: Produzido | K27: 392 | L27: 6 | M27: UO Passo Fundo | N27: RS INT | O27: S | P27: AGUA | T27: 17894900520504 | U27: 7894900520507 | V27: 1280 | W27: KO | X27: =G27 -> 92721 | Y27: CRY SPARKLING LIMAO PET 510ml 6U FL
A28: BFGICrystal Sabores Limao PET 510ml (06) | B28: BFGI1452 | C28: BFGI92721 | D28: 1452 | E28: Crystal Sabores Limao PET 510ml (06) | F28: BFGI | G28: 92721 | H28: CRY SPARKLING LIMAO PET 510ml 6U FL | I28: AGUA | J28: Produzido | K28: 392 | L28: 6 | M28: UO Vera Cruz | N28: RS INT | O28: S | P28: AGUA | T28: 17894900520504 | U28: 7894900520507 | V28: 1280 | W28: KO | X28: =G28 -> 92721 | Y28: CRY SPARKLING LIMAO PET 510ml 6U FL
A29: BFGGCrystal Sabores Melancia PET 510ml (06) | B29: BFGG60435 | C29: BFGG60435 | D29: 60435 | E29: Crystal Sabores Melancia PET 510ml (06) | F29: BFGG | G29: 60435 | H29: Crystal Sabores Novo SaborPet 510ml (06) | I29: AGUA | J29: Produzido | K29: 392 | L29: 6 | M29: UO Santa Maria | N29: RS INT | O29: L01 | P29: AGUA | R29: 44927 | V29: Sem Sku Correspondente | W29: KO | X29: =G29 -> 60435 | Y29: Crystal Sabores Novo SaborPet 510ml (06)
A30: BFGHCrystal Sabores Melancia PET 510ml (06) | B30: BFGH60435 | C30: BFGH60435 | D30: 60435 | E30: Crystal Sabores Melancia PET 510ml (06) | F30: BFGH | G30: 60435 | H30: Crystal Sabores Novo SaborPet 510ml (06) | I30: AGUA | J30: Produzido | K30: 392 | L30: 6 | M30: UO Passo Fundo | N30: RS INT | O30: L01 | P30: AGUA | R30: 44927 | V30: Sem Sku Correspondente | W30: KO | X30: =G30 -> 60435 | Y30: Crystal Sabores Novo SaborPet 510ml (06)
A31: BFGICrystal Sabores Melancia PET 510ml (06) | B31: BFGI60435 | C31: BFGI60435 | D31: 60435 | E31: Crystal Sabores Melancia PET 510ml (06) | F31: BFGI | G31: 60435 | H31: Crystal Sabores Novo SaborPet 510ml (06) | I31: AGUA | J31: Produzido | K31: 392 | L31: 6 | M31: UO Vera Cruz | N31: RS INT | O31: L01 | P31: AGUA | R31: 44927 | V31: Sem Sku Correspondente | W31: KO | X31: =G31 -> 60435 | Y31: Crystal Sabores Novo SaborPet 510ml (06)
A32: BFGGCrystal Sabores Tangerina e Capim Limao PET 510ml (06) | B32: BFGG1305 | C32: BFGG92701 | D32: 1305 | E32: Crystal Sabores Tangerina e Capim Limao PET 510ml (06) | F32: BFGG | G32: 92701 | H32: CRY SPARKLING TANG CAPLIM PET 510ml 6U | I32: AGUA | J32: Produzido | K32: 392 | L32: 6 | M32: UO Santa Maria | N32: RS INT | O32: L10 | P32: AGUA | Q32: Data a definir | R32: 44835 | T32: 17894900521006 | U32: 7894900521009 | V32: Sem Sku Correspondente | W32: KO | X32: =G32 -> 92701 | Y32: CRY SPARKLING TANG CAPLIM PET 510ml 6U
A33: BFGHCrystal Sabores Tangerina e Capim Limao PET 510ml (06) | B33: BFGH1305 | C33: BFGH92701 | D33: 1305 | E33: Crystal Sabores Tangerina e Capim Limao PET 510ml (06) | F33: BFGH | G33: 92701 | H33: CRY SPARKLING TANG CAPLIM PET 510ml 6U | I33: AGUA | J33: Produzido | K33: 392 | L33: 6 | M33: UO Passo Fundo | N33: RS INT | O33: L10 | P33: AGUA | Q33: Data a definir | R33: 44835 | T33: 17894900521006 | U33: 7894900521009 | V33: Sem Sku Correspondente | W33: KO | X33: =G33 -> 92701 | Y33: CRY SPARKLING TANG CAPLIM PET 510ml 6U
A34: BFGICrystal Sabores Tangerina e Capim Limao PET 510ml (06) | B34: BFGI1305 | C34: BFGI92701 | D34: 1305 | E34: Crystal Sabores Tangerina e Capim Limao PET 510ml (06) | F34: BFGI | G34: 92701 | H34: CRY SPARKLING TANG CAPLIM PET 510ml 6U | I34: AGUA | J34: Produzido | K34: 392 | L34: 6 | M34: UO Vera Cruz | N34: RS INT | O34: L10 | P34: AGUA | Q34: Data a definir | R34: 44835 | T34: 17894900521006 | U34: 7894900521009 | V34: Sem Sku Correspondente | W34: KO | X34: =G34 -> 92701 | Y34: CRY SPARKLING TANG CAPLIM PET 510ml 6U
A35: BFGGCrystal Vip C/G PET 350ml (12) | B35: BFGG87 | C35: BFGG92657 | D35: 87 | E35: Crystal Vip C/G PET 350ml (12) | F35: BFGG | G35: 92657 | H35: CRYSTAL VIP CG 350ML 12un CP | I35: AGUA | J35: Produzido | K35: 140 | L35: 12 | M35: UO Santa Maria | N35: RS INT | O35: L10 | P35: AGUA | Q35: Data a definir | R35: 44835 | T35: 17894900531203 | U35: 7894900531206 | V35: Sem Sku Correspondente | W35: KO | X35: =G35 -> 92657 | Y35: CRYSTAL VIP CG 350ML 12un CP
A36: BFGHCrystal Vip C/G PET 350ml (12) | B36: BFGH87 | C36: BFGH92657 | D36: 87 | E36: Crystal Vip C/G PET 350ml (12) | F36: BFGH | G36: 92657 | H36: CRYSTAL VIP CG 350ML 12un CP | I36: AGUA | J36: Produzido | K36: 140 | L36: 12 | M36: UO Passo Fundo | N36: RS INT | O36: L10 | P36: AGUA | Q36: Data a definir | R36: 44835 | T36: 17894900531203 | U36: 7894900531206 | V36: Sem Sku Correspondente | W36: KO | X36: =G36 -> 92657 | Y36: CRYSTAL VIP CG 350ML 12un CP
A37: BFGICrystal Vip C/G PET 350ml (12) | B37: BFGI87 | C37: BFGI92657 | D37: 87 | E37: Crystal Vip C/G PET 350ml (12) | F37: BFGI | G37: 92657 | H37: CRYSTAL VIP CG 350ML 12un CP | I37: AGUA | J37: Produzido | K37: 140 | L37: 12 | M37: UO Vera Cruz | N37: RS INT | O37: L10 | P37: AGUA | Q37: Data a definir | R37: 44835 | T37: 17894900531203 | U37: 7894900531206 | V37: Sem Sku Correspondente | W37: KO | X37: =G37 -> 92657 | Y37: CRYSTAL VIP CG 350ML 12un CP
A38: BFGGCrystal Vip S/G PET 350ml (12) | B38: BFGG88 | C38: BFGG92658 | D38: 88 | E38: Crystal Vip S/G PET 350ml (12) | F38: BFGG | G38: 92658 | H38: CRYSTAL VIP SG 350ML 12UN CP | I38: AGUA | J38: Produzido | K38: 140 | L38: 12 | M38: UO Santa Maria | N38: RS INT | O38: L10 | P38: AGUA | Q38: Data a definir | R38: 44835 | T38: 17894900530206 | U38: 7894900530209 | V38: Sem Sku Correspondente | W38: KO | X38: =G38 -> 92658 | Y38: CRYSTAL VIP SG 350ML 12UN CP
A39: BFGHCrystal Vip S/G PET 350ml (12) | B39: BFGH88 | C39: BFGH92658 | D39: 88 | E39: Crystal Vip S/G PET 350ml (12) | F39: BFGH | G39: 92658 | H39: CRYSTAL VIP SG 350ML 12UN CP | I39: AGUA | J39: Produzido | K39: 140 | L39: 12 | M39: UO Passo Fundo | N39: RS INT | O39: L10 | P39: AGUA | Q39: Data a definir | R39: 44835 | T39: 17894900530206 | U39: 7894900530209 | V39: Sem Sku Correspondente | W39: KO | X39: =G39 -> 92658 | Y39: CRYSTAL VIP SG 350ML 12UN CP
A40: BFGICrystal Vip S/G PET 350ml (12) | B40: BFGI88 | C40: BFGI92658 | D40: 88 | E40: Crystal Vip S/G PET 350ml (12) | F40: BFGI | G40: 92658 | H40: CRYSTAL VIP SG 350ML 12UN CP | I40: AGUA | J40: Produzido | K40: 140 | L40: 12 | M40: UO Vera Cruz | N40: RS INT | O40: L10 | P40: AGUA | Q40: Data a definir | R40: 44835 | T40: 17894900530206 | U40: 7894900530209 | V40: Sem Sku Correspondente | W40: KO | X40: =G40 -> 92658 | Y40: CRYSTAL VIP SG 350ML 12UN CP
...

Sheet LISTA DE PRODUTOS
A1: Código DUN | B1: Código EAN | C1: SKU ECC | D1: Descrição SKU ECC | E1: Categoria | F1: Apresentação
A2: 17894900531012 | B2: 7894900531015 | C2: 92520 | D2: CRYSTAL 1,5L COM GÁS 06UN | E2: AGUA | F2: 6
A3: 17894900531005 | B3: 7894900531008 | C3: 92522 | D3: CRYSTAL 500ML COM GÁS 12UN | E3: AGUA | F3: 12
A4: 7894900530148 | B4: 7894900530049 | C4: 92536 | D4: CRYSTAL COPO 310ML SG 48UN CP . | E4: AGUA | F4: 48
A5: 17894900530053 | B5: 7894900530056 | C5: 92581 | D5: CRYSTAL 05L C/2 CP | E5: AGUA | F5: 2
A6: 17894900530039 | B6: 7894900530032 | C6: 92521 | D6: CRYSTAL 1,5L SEM GÁS 06UN | E6: AGUA | F6: 6
A7: 7894900530278 | B7: 7894900530032 | C7: 92670 | D7: CRYST 1,5L SEM GÁS 08UN PROM FI CP | E7: AGUA | F7: 8
A8: 17894900530008 | B8: 7894900530001 | C8: 92527 | D8: CRYSTAL 500ML SEM GÁS 12UN | E8: AGUA | F8: 12
A9: 17894900521501 | B9: 7894900521504 | C9: 92723 | D9: CRY SPARKLING FRUTAS VERM PET510 6U FL | E9: AGUA | F9: 6
A10: 17894900520504 | B10: 7894900520507 | C10: 92721 | D10: CRY SPARKLING LIMAO PET 510ml 6U FL | E10: AGUA | F10: 6
A11: 17894900523000 | B11: 7894900523003 | C11: 92808 | D11: CRY SPARKLING MELANCIA PET 510 6U FL | E11: AGUA | F11: 6
A12: 17894900521006 | B12: 7894900521009 | C12: 92701 | D12: CRY SPARKLING TANG CAPLIM PET 510ml 6U | E12: AGUA | F12: 6
A13: 17894900531203 | B13: 7894900531206 | C13: 92657 | D13: CRYSTAL VIP CG 350ML 12un CP | E13: AGUA | F13: 12
... A114: 17894900083009 | B114: 7894900083002 | C114: 118952 | D114: ADES SEEDS AMÊNDOAS 1L (6P) CP | E114: BEBIDAS VEGETAIS | F114: 6
C115: 60775 | D115: Ades Seeds Aveia Chocolate 1L (6) | E115: BEBIDAS VEGETAIS | F115: 6
C116: 60774 | D116: Ades Seeds Aveia SAA 1L (6) | E116: BEBIDAS VEGETAIS | F116: 6
A117: 17894900084501 | B117: 7894900084504 | C117: 118954 | D117: ADES SEEDS COCO 1L (6P) CP | E117: BEBIDAS VEGETAIS | F117: 6
A118: 8412598005572 | B118: 7898953990324 | C118: 139594 | D118: 1906 RESERVA ESPECIAL LN 330ml (6) | E118: CERVEJA | F118: 6
A119: 7896045503810 | B119: 7896045503452 | C119: 139065 | D119: BAVARIA LT 473 ML 12 pack | E119: CERVEJA | F119: 12
A120: 7896045503094 | B120: 7896045503094 | C120: 139178 | D120: KAISER CHOPE 30 LTS | E120: CERVEJA | F120: 1
A121: 7896045503100 | B121: 7896045503100 | C121: 139180 | D121: KAI CHCLARO 50L | E121: CERVEJA | F121: 1
A122: 7898367984131 | B122: 7898367983813 | C122: 139615 | D122: EISENBAHN IPA LN 355ML 6U | E122: CERVEJA | F122: 6
A123: 7898367984063 | B123: 7898367984056 | C123: 139486 | D123: Eisenbahn LT 350ml 12U IPA | E123: CERVEJA | F123: 12
A124: 7898367980072 | B124: 7898367980034 | C124: 139614 | D124: EISENBAHN PALE ALE LN 355ML 6U | E124: CERVEJA | F124: 6
A125: 7898367984087 | B125: 7898367984070 | C125: 139485 | D125: Eisenbahn LT 350ml 12U Pale Ale | E125: CERVEJA | F125: 12
C126: 60557 | D126: Eisenbahn Pilsen German LN 355ml (12) | E126: CERVEJA | F126: 12
A127: 7898367983998 | B127: 7898367983998 | C127: 139464 | D127: Eisenbahn KEG 30L 1UN Pilsen | E127: CERVEJA | F127: 1
A128: 7898367984001 | B128: 7898367984001 | C128: 139467 | D128: Eisenbahn KEG 50L 1UN Pilsen | E128: CERVEJA | F128: 1
A129: 7898367980850 | B129: 7898367980010 | C129: 139477 | D129: Eisenbahn LN 355ml 2X6 Pilsen | E129: CERVEJA | F129: 12
A130: 7898367984018 | B130: 7898367983790 | C130: 139474 | D130: Eisenbahn LT 350ml 12U Pilsen | E130: CERVEJA | F130: 12
A131: 7898367984216 | B131: 7898367983356 | C131: 139471 | D131: Eisenbahn LT 473ml 12U Pilsen | E131: CERVEJA | F131: 12
A132: 7898367984162 | B132: 7898367983615 | C132: 139469 | D132: Eisenbahn 600ml 12U Descartável Pilsen | E132: CERVEJA | F132: 12
A133: 7898367983615 | B133: 7898367983615 | C133: 139468 | D133: Eisenbahn 600ml 24U RGB Pilsen | E133: CERVEJA | F133: 24
A134: 7898367984308 | B134: 7898367984254 | C134: 139640 | D134: EISENBAHN IPA HILDA LN 355ML 6U | E134: CERVEJA | F134: 6
A135: 7898367984360 | B135: 7898367984346 | C135: 139647 | D135: EISENBAHN UNFILTERED LN 355ML 2X6 | E135: CERVEJA | F135: 12
A136: 7898367984384 | B136: 7898367984377 | C136: 139648 | D136: EISENBAHN UNFILTERED LT 350ML 12 | E136: CERVEJA | F136: 12
A137: 7898367984452 | B137: 7898367984445 | C137: 139676 | D137: EISENBAHN UNFILTERED GAR VD RGB 600ml 24 | E137: CERVEJA | F137: 24
A138: 7898367980089 | B138: 7898367980041 | C138: 139612 | D138: EISENBAHN WEIZENBIER LN 355ML 6U | E138: CERVEJA | F138: 6
... A181: 17891098040685 | B181: 7891098040688 | C181: 118637 | D181: MATTE LEAO NATURAL PET 450ml (6) CP | E181: CHAS | F181: 6
B182: 7500435201292 | C182: 130024 | D182: AMAC DOWNY + INTENSO BRISA GAR 500ml 1 | E182: CUIDADO COM A CASA | F182: 1
...

Sheet CORRIGIR EAN
A1: EAN | B1: Descrição | C1: SKU | D1: EAN CORRETO | E1: DE/PARA | F1: SKU ECC | G1: Descrição SKU ECC | H1: Categoria
A2: 70847022022 | B2: =VLOOKUP(A2,'Mapa de Produto'!U:Y,5,0) -> Monster JM Khaos LT 473ml 6Pack FL CP | C2: =VLOOKUP(A2,'Mapa de Produto'!U:X,4,0) -> 118464 | D2: INATIVO | E2: 1220000250147 | F2: 118650 | G2: MONSTER KHAOTIC LT 473ML 06 | H2: ENERGETICO
A3: 7894900015041 | B3: =VLOOKUP(A3,'Mapa de Produto'!U:Y,5,0) -> COCA-COLA 290ML VDR RET KS ULTRA | C3: - | D3: 7894900015034 | E3: 7894900015034 | F3: 55957 | G3: COCA-COLA 290ML VDR RET KS ULTRA | H3: REFRIG COLAS
A4: 7894900027044 | B4: =VLOOKUP(A4,'Mapa de Produto'!U:Y,5,0) -> CCOLA PET 1L ORIGINAL DESC C/6 | C4: =VLOOKUP(A4,'Mapa de Produto'!U:X,4,0) -> 56675 | D4: INATIVO | E4: 7894900011715 | F4: 55993 | G4: COCA COLA PET 1L CX C/06 | H4: REFRIG COLAS
A5: 7894900029017 | B5: COCA-COLA SA BAUNILHA PICANTE LT 310ML 6 | C5: 56766 | D5: INATIVO
A7: SKUs fora do portifólio FEMSA
A8: 7892840812423 | B8: H2O
A9: 7891121154009 | B9: Gin SEAGERS
A10: 7893218003603 | B10: APERITIVO SMIRNOFF ICE 275ML
A11: 7896080001401 | B11: Conhaque DOMECQ
